Workbook

Sheet Comece aqui
B2: PROMOVIX
B3: Dados da tabela promocional do mês. Quem preenche: comercial. Quem monta no Figma: /promovix.
B5: PASSO A PASSO
B6: 1. Mês | C6: Troque mês, ano e validade. Os textos das faixas, do selo e do VixClub só mudam se a campanha mudar.
B7: 2. Famílias | C7: Uma linha por família (KODAK SINGLE, OPTVIEW...). Família nova: preencha uma linha nova aqui antes de lançar os produtos.
B8: 3. Produtos | C8: Uma linha por linha impressa, na ordem em que aparece na tabela. Escolha a família na lista e preencha preço e grade.
B9: 4. Páginas | C9: Diga em que página entra cada família e em que ordem. Blocos especiais: CAPA, FAIXA_50, FAIXA_MONTAGEM, VIXCLUB.
B10: 5. Montar | C10: Salve e peça "/promovix" no Claude com este arquivo. Ela confere tudo antes de ir ao Figma e avisa o que estiver errado.
B12: LEGENDA
B13: Faixa amarela | C13: Grupo de colunas.
B14: Título preto | C14: Coluna para preencher. Passe o mouse no título: a nota explica o campo.
B15: Título cinza | C15: Coluna automática, só para conferência. Não precisa mexer.
B16: Seta na célula | C16: Lista suspensa: escolha em vez de digitar.
B18: REGRAS QUE A SKILL CONFERE
B19: Regra 50% | C19: Nas famílias com Regra 50% = S, deixe Reflecta Guard e Blue em branco: a skill calcula Sem A.R. + acréscimos da aba Mês. Se preencher, ela confere.
B20: Transitions | C20: Escreva "Transitions Gen S" ou "Transitions XTRActive" no nome do produto. A pílula colorida sai sozinha, não precisa marcar nada.
B21: Cores | C21: Códigos por cor no formato "8110 Cinza; 8111 Marrom". Ordem Gen S: Cinza, Marrom, Verde, Ametista, Safira, Âmbar, Esmeralda, Rubi.
B22: Seta ↓ | C22: Código vazio + 2 ou mais cores = a linha sai com ↓ e os códigos aparecem na linha de bolinhas logo abaixo.
B23: Preço | C23: A skill lê, confere e monta. Ela não inventa valor: preço é decisão de quem preenche.

Sheet Mês
A1: Campo | B1: Valor | C1: Dica | D1: chave
A2: PERÍODO
A3: Mês | B3: OUTUBRO | C3: Em maiúsculas: OUTUBRO, NOVEMBRO... | D3: mes
A4: Ano (2 dígitos) | B4: 26 | C4: Dois dígitos. | D4: ano
A5: Validade | B5: 01/10/26 A 31/10/26 | C5: Aparece na capa e no rodapé de todas as páginas. | D5: validade
A6: REGRA 50% (REFLECTA)
A7: Acréscimo Reflecta Guard | B7: 42.5 | C7: Regra 50%: Reflecta Guard = Sem A.R. + este valor. | D7: acrescimo_guard
A8: Acréscimo Reflecta Blue Protect SH | B8: 99.5 | C8: Regra 50%: Reflecta Blue Protect SH = Sem A.R. + este valor. | D8: acrescimo_blue
A9: SELO DE OFERTA
A10: Texto do selo nas colunas em promoção | B10: REFLECTA −50% | C10: Adesivo preto sobre as colunas em promoção (coluna Colunas em promoção, aba Famílias). Vazio = sem adesivo. | D10: adesivo_promo
A11: FAIXA 50%
A12: Texto antes do número | B12: Reflecta com | C12: Texto antes do número. | D12: faixa50_antes
A13: Número grande | B13: 50% | C13: Número grande em amarelo. | D13: faixa50_destaque
A14: Texto depois do número | B14: DE DESCONTO | C14: Texto depois do número. | D14: faixa50_depois
A15: Texto da direita | B15: Em toda linha KODAK, ESPACE PLUS DIGITAL e ESSILOR VISÃO SIMPLES SURFAÇADAS | C15: Texto da direita. Quebra de linha com Alt+Enter. | D15: faixa50_direita
A16: MONTAGEM DE LENTE PRONTA
A17: Rótulo do selo no cabeçalho | B17: MONTAGEM LENTE PRONTA | C17: Aparece nas famílias com Selo de montagem = S. Quebra de linha com Alt+Enter. | D17: montagem_selo
A18: Valor | B18: R$15 | C18: Valor grande em amarelo. | D18: montagem_destaque
A19: Faixa: texto antes do valor | B19: Montagem de lente pronta por | C19: Só se usar o bloco FAIXA_MONTAGEM em Páginas. O padrão hoje é o selo no cabeçalho. | D19: montagem_antes
A20: Faixa: texto da direita | B20: Em toda linha de LENTES PRONTAS E ACABADAS | C20: Só se usar o bloco FAIXA_MONTAGEM. Quebra de linha com Alt+Enter. | D20: montagem_direita
A21: PAINEL VIXCLUB
A22: Título | B22: Sua ótica cresce melhor quando tem parceria de verdade. | C22: Título. | D22: vixclub_titulo
A23: Texto | B23: Com o VixClub, você acessa benefícios exclusivos, condições especiais e soluções pensadas para fortalecer o seu negócio. Fale com um consultor e saiba mais. | C23: Texto. | D23: vixclub_texto
A24: CAPA E RODAPÉ
A25: Aviso da capa | B25: Disponibilidades técnicas sujeitas à consulta em tabela. | C25: Capa. | D25: aviso
A26: Instagram | B26: @vixlens | C26: Rodapé. | D26: instagram
A27: Telefone | B27: 27 3061-2626 | C27: Rodapé. | D27: telefone
A28: Site | B28: vixlens.com.br | C28: Rodapé. | D28: site

Sheet Famílias
A1: FAMÍLIA | E1: COLUNAS DE PREÇO | H1: LAYOUT | O1: CONFERÊNCIA
A2: Família | B2: Subtítulo | C2: Cor (hex) | D2: Pílulas do cabeçalho | E2: Colunas de preço | F2: Colunas em promoção | G2: Regra 50% | H2: Faixa ÍNDICE | I2: Coluna Tratamento | J2: Título da Disponibilidade | K2: Largura da Disponibilidade | L2: Legenda de destaque | M2: Selo de montagem | N2: Bloco compacto | O2: Produtos | P2: Página
A3: OPTFÁCIL GO | B3: LENTES MULTIFOCAIS DIGITAIS | C3: #DADFE2 | D3: Cil. até -2.00;Add. 1.00 a 3.50 | E3: Sem A.R.;A.R. Eco;Reflecta Express | G3: N | H3: N | I3: N | K3: 70 | L3: N | M3: N | N3: N | O3: =IF(A3="","",COUNTIF(Produtos!$A:$A,A3)) | P3: =IF(A3="","",IFERROR(INDEX('Páginas'!$A:$A,MATCH(A3,'Páginas'!$B:$B,0)),"FALTA"))
A4: VIX TOTAL | B4: LENTES MULTIFOCAIS FREEFORM // MARCA PRÓPRIA VIXLENS | C4: #F7B200 | D4: Alt. mín. 18 mm;Cil. até -4.00;Add. 1.00 a 3.50 | E4: Sem A.R.;Reflecta Express;Reflecta Guard | G4: N | H4: S | I4: N | K4: 70 | L4: N | M4: N | N4: N | O4: =IF(A4="","",COUNTIF(Produtos!$A:$A,A4)) | P4: =IF(A4="","",IFERROR(INDEX('Páginas'!$A:$A,MATCH(A4,'Páginas'!$B:$B,0)),"FALTA"))
A5: FREEVIX VISÃO SIMPLES | B5: LENTES DE VISÃO SIMPLES SURFAÇADAS // MARCA PRÓPRIA VIXLENS | C5: #00497A | D5: Cil. até -4.00 | E5: Sem A.R.;Reflecta Express;Reflecta Guard | G5: N | H5: S | I5: N | K5: 70 | L5: N | M5: N | N5: N | O5: =IF(A5="","",COUNTIF(Produtos!$A:$A,A5)) | P5: =IF(A5="","",IFERROR(INDEX('Páginas'!$A:$A,MATCH(A5,'Páginas'!$B:$B,0)),"FALTA"))
A6: SOLAR ACABADA | B6: LENTES DE VISÃO SIMPLES SOLARES ACABADAS | C6: #DADFE2 | E6: Par | G6: N | H6: N | I6: N | J6: Curva | Diâm. | K6: 92 | L6: N | M6: N | N6: S | O6: =IF(A6="","",COUNTIF(Produtos!$A:$A,A6)) | P6: =IF(A6="","",IFERROR(INDEX('Páginas'!$A:$A,MATCH(A6,'Páginas'!$B:$B,0)),"FALTA"))
A7: ESPACE PLUS DIGITAL | B7: LENTES MULTIFOCAIS DIGITAIS // ESSILOR | C7: #EF7F02 | D7: Cil. até -6.00;Add. 1.00 a 3.50 | E7: Sem A.R.;Reflecta Guard;Reflecta Blue Protect SH | F7: 2;3 | G7: S | H7: N | I7: N | K7: 70 | L7: N | M7: N | N7: N | O7: =IF(A7="","",COUNTIF(Produtos!$A:$A,A7)) | P7: =IF(A7="","",IFERROR(INDEX('Páginas'!$A:$A,MATCH(A7,'Páginas'!$B:$B,0)),"FALTA"))
A8: KODAK PRECISE NEXT | B8: LENTES MULTIFOCAIS DIGITAIS // LENTES KODAK | C8: #F7B200 | D8: Cil. até -6.00;Add. 1.00 a 3.50 | E8: Sem A.R.;Reflecta Guard;Reflecta Blue Protect SH | F8: 2;3 | G8: S | H8: N | I8: N | K8: 70 | L8: N | M8: N | N8: N | O8: =IF(A8="","",COUNTIF(Produtos!$A:$A,A8)) | P8: =IF(A8="","",IFERROR(INDEX('Páginas'!$A:$A,MATCH(A8,'Páginas'!$B:$B,0)),"FALTA"))
A9: KODAK NETWORK UHD | B9: LENTES MULTIFOCAIS DIGITAIS // LENTES KODAK | C9: #F7B200 | D9: Cil. até -6.00;Add. 1.00 a 3.50 | E9: Sem A.R.;Reflecta Guard;Reflecta Blue Protect SH | F9: 2;3 | G9: S | H9: N | I9: N | K9: 70 | L9: N | M9: N | N9: N | O9: =IF(A9="","",COUNTIF(Produtos!$A:$A,A9)) | P9: =IF(A9="","",IFERROR(INDEX('Páginas'!$A:$A,MATCH(A9,'Páginas'!$B:$B,0)),"FALTA"))
A10: KODAK SOFTWEAR | B10: LENTES OCUPACIONAIS DIGITAIS // LENTES KODAK | C10: #F7B200 | D10: Cil. até -6.00;Add. 1.00 a 3.50 | E10: Sem A.R.;Reflecta Guard;Reflecta Blue Protect SH | F10: 2;3 | G10: S | H10: N | I10: N | K10: 70 | L10: N | M10: N | N10: N | O10: =IF(A10="","",COUNTIF(Produtos!$A:$A,A10)) | P10: =IF(A10="","",IFERROR(INDEX('Páginas'!$A:$A,MATCH(A10,'Páginas'!$B:$B,0)),"FALTA"))
A11: KODAK UNIQUE UHD | B11: LENTES MULTIFOCAIS DIGITAIS // LENTES KODAK | C11: #F7B200 | D11: Cil. até -6.00;Add. 1.00 a 3.50 | E11: Sem A.R.;Reflecta Guard;Reflecta Blue Protect SH | F11: 2;3 | G11: S | H11: N | I11: N | K11: 70 | L11: N | M11: N | N11: N | O11: =IF(A11="","",COUNTIF(Produtos!$A:$A,A11)) | P11: =IF(A11="","",IFERROR(INDEX('Páginas'!$A:$A,MATCH(A11,'Páginas'!$B:$B,0)),"FALTA"))
A12: KODAK UNIQUE INFINITE | B12: LENTES MULTIFOCAIS DIGITAIS // LENTES KODAK | C12: #F7B200 | D12: Cil. até -6.00;Add. 0.75 a 3.50 | E12: Sem A.R.;Reflecta Guard;Reflecta Blue Protect SH | F12: 2;3 | G12: S | H12: N | I12: N | K12: 70 | L12: N | M12: N | N12: N | O12: =IF(A12="","",COUNTIF(Produtos!$A:$A,A12)) | P12: =IF(A12="","",IFERROR(INDEX('Páginas'!$A:$A,MATCH(A12,'Páginas'!$B:$B,0)),"FALTA"))
A13: KODAK SINGLE | B13: LENTES DE VISÃO SIMPLES DIGITAIS // LENTES KODAK | C13: #F7B200 | D13: Cil. até -6.00 | E13: Sem A.R.;Reflecta Guard;Reflecta Blue Protect SH | F13: 2;3 | G13: S | H13: N | I13: N | K13: 70 | L13: N | M13: N | N13: N | O13: =IF(A13="","",COUNTIF(Produtos!$A:$A,A13)) | P13: =IF(A13="","",IFERROR(INDEX('Páginas'!$A:$A,MATCH(A13,'Páginas'!$B:$B,0)),"FALTA"))
A14: ESSILOR SURFAÇADAS | B14: LENTES DE VISÃO SIMPLES SURFAÇADAS // ESSILOR | C14: #3F4A3C | D14: Cil. até -6.00 | E14: Sem A.R.;Reflecta Guard;Reflecta Blue Protect SH | F14: 2;3 | G14: S | H14: N | I14: N | K14: 70 | L14: N | M14: N | N14: N | O14: =IF(A14="","",COUNTIF(Produtos!$A:$A,A14)) | P14: =IF(A14="","",IFERROR(INDEX('Páginas'!$A:$A,MATCH(A14,'Páginas'!$B:$B,0)),"FALTA"))
A15: OPTVIEW | B15: LENTES DE VISÃO SIMPLES ACABADAS | C15: #D0DDE4 | E15: Par | G15: N | H15: N | I15: S | K15: 92 | L15: S | M15: S | N15: N | O15: =IF(A15="","",COUNTIF(Produtos!$A:$A,A15)) | P15: =IF(A15="","",IFERROR(INDEX('Páginas'!$A:$A,MATCH(A15,'Páginas'!$B:$B,0)),"FALTA"))
A16: MULTIFOCAL ACABADA | B16: LENTES MULTIFOCAIS ACABADAS | C16: #D0DDE4 | E16: Par | G16: N | H16: N | I16: S | K16: 92 | L16: S | M16: N | N16: N | O16: =IF(A16="","",COUNTIF(Produtos!$A:$A,A16)) | P16: =IF(A16="","",IFERROR(INDEX('Páginas'!$A:$A,MATCH(A16,'Páginas'!$B:$B,0)),"FALTA"))
A17: LENTE PRONTA KODAK | B17: LENTES DE VISÃO SIMPLES PRONTAS // LENTES KODAK | C17: #F7B200 | E17: Par | G17: N | H17: N | I17: N | K17: 95 | L17: S | M17: S | N17: N | O17: =IF(A17="","",COUNTIF(Produtos!$A:$A,A17)) | P17: =IF(A17="","",IFERROR(INDEX('Páginas'!$A:$A,MATCH(A17,'Páginas'!$B:$B,0)),"FALTA"))
A18: LENTE PRONTA ESSILOR | B18: LENTES DE VISÃO SIMPLES PRONTAS // ESSILOR | C18: #414B55 | E18: Par | G18: N | H18: N | I18: N | K18: 95 | L18: N | M18: N | N18: N | O18: =IF(A18="","",COUNTIF(Produtos!$A:$A,A18)) | P18: =IF(A18="","",IFERROR(INDEX('Páginas'!$A:$A,MATCH(A18,'Páginas'!$B:$B,0)),"FALTA"))
O19: =IF(A19="","",COUNTIF(Produtos!$A:$A,A19)) | P19: =IF(A19="","",IFERROR(INDEX('Páginas'!$A:$A,MATCH(A19,'Páginas'!$B:$B,0)),"FALTA"))
O20: =IF(A20="","",COUNTIF(Produtos!$A:$A,A20)) | P20: =IF(A20="","",IFERROR(INDEX('Páginas'!$A:$A,MATCH(A20,'Páginas'!$B:$B,0)),"FALTA"))
O21: =IF(A21="","",COUNTIF(Produtos!$A:$A,A21)) | P21: =IF(A21="","",IFERROR(INDEX('Páginas'!$A:$A,MATCH(A21,'Páginas'!$B:$B,0)),"FALTA"))
O22: =IF(A22="","",COUNTIF(Produtos!$A:$A,A22)) | P22: =IF(A22="","",IFERROR(INDEX('Páginas'!$A:$A,MATCH(A22,'Páginas'!$B:$B,0)),"FALTA"))
O23: =IF(A23="","",COUNTIF(Produtos!$A:$A,A23)) | P23: =IF(A23="","",IFERROR(INDEX('Páginas'!$A:$A,MATCH(A23,'Páginas'!$B:$B,0)),"FALTA"))
O24: =IF(A24="","",COUNTIF(Produtos!$A:$A,A24)) | P24: =IF(A24="","",IFERROR(INDEX('Páginas'!$A:$A,MATCH(A24,'Páginas'!$B:$B,0)),"FALTA"))
O25: =IF(A25="","",COUNTIF(Produtos!$A:$A,A25)) | P25: =IF(A25="","",IFERROR(INDEX('Páginas'!$A:$A,MATCH(A25,'Páginas'!$B:$B,0)),"FALTA"))
O26: =IF(A26="","",COUNTIF(Produtos!$A:$A,A26)) | P26: =IF(A26="","",IFERROR(INDEX('Páginas'!$A:$A,MATCH(A26,'Páginas'!$B:$B,0)),"FALTA"))
O27: =IF(A27="","",COUNTIF(Produtos!$A:$A,A27)) | P27: =IF(A27="","",IFERROR(INDEX('Páginas'!$A:$A,MATCH(A27,'Páginas'!$B:$B,0)),"FALTA"))
O28: =IF(A28="","",COUNTIF(Produtos!$A:$A,A28)) | P28: =IF(A28="","",IFERROR(INDEX('Páginas'!$A:$A,MATCH(A28,'Páginas'!$B:$B,0)),"FALTA"))
O29: =IF(A29="","",COUNTIF(Produtos!$A:$A,A29)) | P29: =IF(A29="","",IFERROR(INDEX('Páginas'!$A:$A,MATCH(A29,'Páginas'!$B:$B,0)),"FALTA"))
O30: =IF(A30="","",COUNTIF(Produtos!$A:$A,A30)) | P30: =IF(A30="","",IFERROR(INDEX('Páginas'!$A:$A,MATCH(A30,'Páginas'!$B:$B,0)),"FALTA"))
... O80: =IF(A80="","",COUNTIF(Produtos!$A:$A,A80)) | P80: =IF(A80="","",IFERROR(INDEX('Páginas'!$A:$A,MATCH(A80,'Páginas'!$B:$B,0)),"FALTA"))

Sheet Produtos
A1: PRODUTO | E1: MARCAÇÕES | J1: DISPONIBILIDADE | Q1: PREÇOS | W1: CORES TRANSITIONS / SOLAR
A2: Família | B2: Código | C2: Índice | D2: Nome do produto | E2: Blue UV | F2: Ponto | G2: Destaque | H2: Tratamento | I2: Pontos do tratamento | J2: Esf. máx | K2: Esf. mín | L2: Cil. | M2: Add. | N2: Diâm. | O2: Curva | P2: Linha extra | Q2: Colunas desta família | R2: Preço 1 | S2: Preço 2 | T2: Preço 3 | U2: Preço 4 | V2: Obs. do preço | W2: Cores e códigos
A3: OPTFÁCIL GO | B3: 7300 | C3: 1.49 | D3: Resina | J3: 4 | K3: -4 | Q3: =IF(A3="","",IFERROR(INDEX('Famílias'!$E:$E,MATCH(A3,'Famílias'!$A:$A,0)),"família não cadastrada")) | R3: 76 | S3: 91 | T3: 101
A4: OPTFÁCIL GO | B4: 7302 | C4: 1.49 | D4: Resina Foto | J4: 4 | K4: -4 | Q4: =IF(A4="","",IFERROR(INDEX('Famílias'!$E:$E,MATCH(A4,'Famílias'!$A:$A,0)),"família não cadastrada")) | R4: 109 | S4: 124 | T4: 134
A5: OPTFÁCIL GO | B5: 7301 | C5: 1.56 | D5: Resina UV+ | J5: 4 | K5: -4 | Q5: =IF(A5="","",IFERROR(INDEX('Famílias'!$E:$E,MATCH(A5,'Famílias'!$A:$A,0)),"família não cadastrada")) | R5: 90 | S5: 105 | T5: 115
A6: OPTFÁCIL GO | B6: 7306 | C6: 1.59 | D6: Poli | J6: 4 | K6: -4 | Q6: =IF(A6="","",IFERROR(INDEX('Famílias'!$E:$E,MATCH(A6,'Famílias'!$A:$A,0)),"família não cadastrada")) | R6: 92 | S6: 107 | T6: 117
A7: VIX TOTAL | B7: 0006 | C7: 1.49 | D7: Resina | J7: 4 | K7: -6 | N7: 75 | Q7: =IF(A7="","",IFERROR(INDEX('Famílias'!$E:$E,MATCH(A7,'Famílias'!$A:$A,0)),"família não cadastrada")) | R7: 85 | S7: 110 | T7: 145
A8: VIX TOTAL | B8: 0009 | C8: 1.49 | D8: Resina Sun+ | J8: 6 | K8: -8 | N8: 75 | Q8: =IF(A8="","",IFERROR(INDEX('Famílias'!$E:$E,MATCH(A8,'Famílias'!$A:$A,0)),"família não cadastrada")) | R8: 129 | S8: 154 | T8: 189
A9: VIX TOTAL | C9: 1.49 | D9: Resina Transitions Gen S | J9: 5 | K9: -6 | N9: 76 | Q9: =IF(A9="","",IFERROR(INDEX('Famílias'!$E:$E,MATCH(A9,'Famílias'!$A:$A,0)),"família não cadastrada")) | R9: 229 | S9: 254 | T9: 289 | V9: 2: só Cinza 0012 | W9: 0012 Cinza; 0671 Marrom; 0672 Verde; 0675 Ametista; 0674 Safira; 1030 Âmbar; 0673 Esmeralda; 1031 Rubi
A10: VIX TOTAL | B10: 0574 | C10: 1.56 | D10: Resina UV+ | J10: 6 | K10: -8 | N10: 75 | Q10: =IF(A10="","",IFERROR(INDEX('Famílias'!$E:$E,MATCH(A10,'Famílias'!$A:$A,0)),"família não cadastrada")) | R10: 122 | S10: 147 | T10: 182
A11: VIX TOTAL | B11: 0573 | C11: 1.56 | D11: Resina Sun+ UV+ | J11: 6 | K11: -6 | N11: 75 | Q11: =IF(A11="","",IFERROR(INDEX('Famílias'!$E:$E,MATCH(A11,'Famílias'!$A:$A,0)),"família não cadastrada")) | R11: 198 | T11: 258
A12: VIX TOTAL | B12: 0013 | C12: 1.59 | D12: Poli | J12: 6 | K12: -8 | N12: 75 | Q12: =IF(A12="","",IFERROR(INDEX('Famílias'!$E:$E,MATCH(A12,'Famílias'!$A:$A,0)),"família não cadastrada")) | R12: 125 | S12: 150 | T12: 185
A13: VIX TOTAL | B13: 0575 | C13: 1.59 | D13: Poli UV+ | J13: 6 | K13: -8 | N13: 75 | Q13: =IF(A13="","",IFERROR(INDEX('Famílias'!$E:$E,MATCH(A13,'Famílias'!$A:$A,0)),"família não cadastrada")) | R13: 169 | T13: 229
A14: VIX TOTAL | B14: 0014 | C14: 1.59 | D14: Poli Sun+ UV+ | J14: 6 | K14: -8 | N14: 75 | Q14: =IF(A14="","",IFERROR(INDEX('Famílias'!$E:$E,MATCH(A14,'Famílias'!$A:$A,0)),"família não cadastrada")) | R14: 259 | T14: 319
A15: VIX TOTAL | C15: 1.59 | D15: Poli Transitions Gen S | J15: 6 | K15: -8 | N15: 75 | Q15: =IF(A15="","",IFERROR(INDEX('Famílias'!$E:$E,MATCH(A15,'Famílias'!$A:$A,0)),"família não cadastrada")) | R15: 399 | T15: 459 | W15: 0576 Cinza; 7408 Marrom; 7411 Verde; 7410 Ametista; 7409 Safira; 7407 Âmbar; 1072 Esmeralda; 1073 Rubi
A16: VIX TOTAL | B16: 0577 | C16: 1.67 | D16: Resina | J16: 7 | K16: -9 | N16: 70 | Q16: =IF(A16="","",IFERROR(INDEX('Famílias'!$E:$E,MATCH(A16,'Famílias'!$A:$A,0)),"família não cadastrada")) | R16: 259 | S16: 284 | T16: 319
A17: VIX TOTAL | B17: 0578 | C17: 1.67 | D17: Resina UV+ | J17: 7 | K17: -9 | N17: 70 | Q17: =IF(A17="","",IFERROR(INDEX('Famílias'!$E:$E,MATCH(A17,'Famílias'!$A:$A,0)),"família não cadastrada")) | R17: 279 | S17: 304 | T17: 339
A18: VIX TOTAL | B18: 0579 | C18: 1.67 | D18: Resina Sun+ UV+ | J18: 7 | K18: -9 | N18: 75 | Q18: =IF(A18="","",IFERROR(INDEX('Famílias'!$E:$E,MATCH(A18,'Famílias'!$A:$A,0)),"família não cadastrada")) | R18: 469 | T18: 529
A19: FREEVIX VISÃO SIMPLES | B19: 0057 | C19: 1.49 | D19: Resina | J19: 4 | K19: -5 | Q19: =IF(A19="","",IFERROR(INDEX('Famílias'!$E:$E,MATCH(A19,'Famílias'!$A:$A,0)),"família não cadastrada")) | R19: 70 | S19: 95 | T19: 130
A20: FREEVIX VISÃO SIMPLES | B20: 0058 | C20: 1.49 | D20: Resina Sun+ | J20: 4 | K20: -5 | Q20: =IF(A20="","",IFERROR(INDEX('Famílias'!$E:$E,MATCH(A20,'Famílias'!$A:$A,0)),"família não cadastrada")) | R20: 105 | S20: 130 | T20: 165
A21: FREEVIX VISÃO SIMPLES | C21: 1.49 | D21: Resina Transitions Gen S | J21: 4 | K21: -4 | Q21: =IF(A21="","",IFERROR(INDEX('Famílias'!$E:$E,MATCH(A21,'Famílias'!$A:$A,0)),"família não cadastrada")) | R21: 209 | S21: 234 | T21: 269 | V21: 2: só Cinza 0059 | W21: 0059 Cinza; 0691 Marrom; 0692 Verde; 0693 Ametista; 0694 Safira; 0695 Âmbar; 1040 Esmeralda; 1041 Rubi
A22: FREEVIX VISÃO SIMPLES | B22: 0060 | C22: 1.56 | D22: Resina UV+ | J22: 4 | K22: -5 | Q22: =IF(A22="","",IFERROR(INDEX('Famílias'!$E:$E,MATCH(A22,'Famílias'!$A:$A,0)),"família não cadastrada")) | R22: 89 | S22: 114 | T22: 149
A23: FREEVIX VISÃO SIMPLES | B23: 0571 | C23: 1.56 | D23: Resina Sun+ UV+ | J23: 4 | K23: -5 | Q23: =IF(A23="","",IFERROR(INDEX('Famílias'!$E:$E,MATCH(A23,'Famílias'!$A:$A,0)),"família não cadastrada")) | R23: 185 | T23: 245
A24: FREEVIX VISÃO SIMPLES | B24: 0061 | C24: 1.59 | D24: Poli | J24: 6 | K24: -6 | Q24: =IF(A24="","",IFERROR(INDEX('Famílias'!$E:$E,MATCH(A24,'Famílias'!$A:$A,0)),"família não cadastrada")) | R24: 89 | S24: 114 | T24: 149
A25: FREEVIX VISÃO SIMPLES | B25: 0062 | C25: 1.59 | D25: Poli UV+ | J25: 6 | K25: -6 | Q25: =IF(A25="","",IFERROR(INDEX('Famílias'!$E:$E,MATCH(A25,'Famílias'!$A:$A,0)),"família não cadastrada")) | R25: 110 | T25: 170
A26: FREEVIX VISÃO SIMPLES | B26: 0591 | C26: 1.59 | D26: Poli Sun+ UV+ | J26: 6 | K26: -6 | Q26: =IF(A26="","",IFERROR(INDEX('Famílias'!$E:$E,MATCH(A26,'Famílias'!$A:$A,0)),"família não cadastrada")) | R26: 229 | T26: 289
A27: FREEVIX VISÃO SIMPLES | C27: 1.59 | D27: Poli Transitions Gen S | J27: 6 | K27: -5 | Q27: =IF(A27="","",IFERROR(INDEX('Famílias'!$E:$E,MATCH(A27,'Famílias'!$A:$A,0)),"família não cadastrada")) | R27: 399 | T27: 459 | W27: 0063 Cinza; 7403 Marrom; 7406 Verde; 7402 Ametista; 7401 Safira; 7400 Âmbar; 7404 Esmeralda; 7405 Rubi
A28: FREEVIX VISÃO SIMPLES | B28: 0064 | C28: 1.67 | D28: Resina | J28: 7 | K28: -9 | Q28: =IF(A28="","",IFERROR(INDEX('Famílias'!$E:$E,MATCH(A28,'Famílias'!$A:$A,0)),"família não cadastrada")) | R28: 199 | S28: 224 | T28: 259
A29: FREEVIX VISÃO SIMPLES | B29: 0065 | C29: 1.67 | D29: Resina UV+ | J29: 7 | K29: -9 | Q29: =IF(A29="","",IFERROR(INDEX('Famílias'!$E:$E,MATCH(A29,'Famílias'!$A:$A,0)),"família não cadastrada")) | R29: 229 | S29: 254 | T29: 289
A30: FREEVIX VISÃO SIMPLES | B30: 0572 | C30: 1.67 | D30: Resina Sun+ UV+ | J30: 7 | K30: -9 | Q30: =IF(A30="","",IFERROR(INDEX('Famílias'!$E:$E,MATCH(A30,'Famílias'!$A:$A,0)),"família não cadastrada")) | R30: 399 | T30: 459
A31: SOLAR ACABADA | B31: 0357 | C31: 1.56 | D31: Solar G15 | N31: 70 | O31: 6 | Q31: =IF(A31="","",IFERROR(INDEX('Famílias'!$E:$E,MATCH(A31,'Famílias'!$A:$A,0)),"família não cadastrada")) | R31: 25 | W31: G15
A32: SOLAR ACABADA | B32: 0359 | C32: 1.56 | D32: Solar Cinza Black | N32: 70 | O32: 6 | Q32: =IF(A32="","",IFERROR(INDEX('Famílias'!$E:$E,MATCH(A32,'Famílias'!$A:$A,0)),"família não cadastrada")) | R32: 25 | W32: Cinza
A33: SOLAR ACABADA | B33: 0360 | C33: 1.56 | D33: Solar Marrom Dark | N33: 70 | O33: 6 | Q33: =IF(A33="","",IFERROR(INDEX('Famílias'!$E:$E,MATCH(A33,'Famílias'!$A:$A,0)),"família não cadastrada")) | R33: 25 | W33: Marrom
A34: SOLAR ACABADA | B34: 0363 | C34: 1.56 | D34: Solar Resina G15 Degradê | N34: 70 | O34: 6 | Q34: =IF(A34="","",IFERROR(INDEX('Famílias'!$E:$E,MATCH(A34,'Famílias'!$A:$A,0)),"família não cadastrada")) | R34: 32 | W34: G15
A35: SOLAR ACABADA | B35: 0362 | C35: 1.56 | D35: Solar Resina Cinza Black Degradê | N35: 70 | O35: 6 | Q35: =IF(A35="","",IFERROR(INDEX('Famílias'!$E:$E,MATCH(A35,'Famílias'!$A:$A,0)),"família não cadastrada")) | R35: 32 | W35: Cinza
A36: SOLAR ACABADA | B36: 0361 | C36: 1.56 | D36: Solar Resina Marrom Degradê | N36: 70 | O36: 6 | Q36: =IF(A36="","",IFERROR(INDEX('Famílias'!$E:$E,MATCH(A36,'Famílias'!$A:$A,0)),"família não cadastrada")) | R36: 32 | W36: Marrom
A37: ESPACE PLUS DIGITAL | B37: 8125 | C37: 1.50 | D37: Orma | J37: 5.25 | K37: -10.25 | Q37: =IF(A37="","",IFERROR(INDEX('Famílias'!$E:$E,MATCH(A37,'Famílias'!$A:$A,0)),"família não cadastrada")) | R37: 125
A38: ESPACE PLUS DIGITAL | B38: 8126 | C38: 1.50 | D38: Orma | E38: S | J38: 5.25 | K38: -10.25 | Q38: =IF(A38="","",IFERROR(INDEX('Famílias'!$E:$E,MATCH(A38,'Famílias'!$A:$A,0)),"família não cadastrada")) | R38: 159.9
A39: ESPACE PLUS DIGITAL | C39: 1.50 | D39: Orma Transitions Gen S | E39: S | J39: 5.25 | K39: -10 | Q39: =IF(A39="","",IFERROR(INDEX('Famílias'!$E:$E,MATCH(A39,'Famílias'!$A:$A,0)),"família não cadastrada")) | R39: 229 | W39: 8127 Cinza; 87000 Marrom; 87001 Verde
A40: ESPACE PLUS DIGITAL | B40: 8129 | C40: 1.59 | D40: Poly | E40: S | J40: 6.5 | K40: -11.75 | Q40: =IF(A40="","",IFERROR(INDEX('Famílias'!$E:$E,MATCH(A40,'Famílias'!$A:$A,0)),"família não cadastrada")) | R40: 169.9
...

Sheet Páginas
A1: ORDEM DAS PÁGINAS | C1: CONFERÊNCIA
A2: Página | B2: Bloco | C2: O que entra
A3: 1 | B3: CAPA | C3: =IF(B3="","",IF(B3="CAPA","Cabeçalho da capa",IF(B3="FAIXA_50","Faixa Reflecta 50%",IF(B3="FAIXA_MONTAGEM","Faixa de montagem",IF(B3="VIXCLUB","Painel VixClub (ocupa o que sobrar)",COUNTIF(Produtos!$A:$A,B3)&" produtos")))))
A4: 1 | B4: OPTFÁCIL GO | C4: =IF(B4="","",IF(B4="CAPA","Cabeçalho da capa",IF(B4="FAIXA_50","Faixa Reflecta 50%",IF(B4="FAIXA_MONTAGEM","Faixa de montagem",IF(B4="VIXCLUB","Painel VixClub (ocupa o que sobrar)",COUNTIF(Produtos!$A:$A,B4)&" produtos")))))
A5: 1 | B5: VIX TOTAL | C5: =IF(B5="","",IF(B5="CAPA","Cabeçalho da capa",IF(B5="FAIXA_50","Faixa Reflecta 50%",IF(B5="FAIXA_MONTAGEM","Faixa de montagem",IF(B5="VIXCLUB","Painel VixClub (ocupa o que sobrar)",COUNTIF(Produtos!$A:$A,B5)&" produtos")))))
A6: 2 | B6: FREEVIX VISÃO SIMPLES | C6: =IF(B6="","",IF(B6="CAPA","Cabeçalho da capa",IF(B6="FAIXA_50","Faixa Reflecta 50%",IF(B6="FAIXA_MONTAGEM","Faixa de montagem",IF(B6="VIXCLUB","Painel VixClub (ocupa o que sobrar)",COUNTIF(Produtos!$A:$A,B6)&" produtos")))))
A7: 2 | B7: VIXCLUB | C7: =IF(B7="","",IF(B7="CAPA","Cabeçalho da capa",IF(B7="FAIXA_50","Faixa Reflecta 50%",IF(B7="FAIXA_MONTAGEM","Faixa de montagem",IF(B7="VIXCLUB","Painel VixClub (ocupa o que sobrar)",COUNTIF(Produtos!$A:$A,B7)&" produtos")))))
A8: 3 | B8: FAIXA_50 | C8: =IF(B8="","",IF(B8="CAPA","Cabeçalho da capa",IF(B8="FAIXA_50","Faixa Reflecta 50%",IF(B8="FAIXA_MONTAGEM","Faixa de montagem",IF(B8="VIXCLUB","Painel VixClub (ocupa o que sobrar)",COUNTIF(Produtos!$A:$A,B8)&" produtos")))))
A9: 3 | B9: ESPACE PLUS DIGITAL | C9: =IF(B9="","",IF(B9="CAPA","Cabeçalho da capa",IF(B9="FAIXA_50","Faixa Reflecta 50%",IF(B9="FAIXA_MONTAGEM","Faixa de montagem",IF(B9="VIXCLUB","Painel VixClub (ocupa o que sobrar)",COUNTIF(Produtos!$A:$A,B9)&" produtos")))))
A10: 3 | B10: KODAK PRECISE NEXT | C10: =IF(B10="","",IF(B10="CAPA","Cabeçalho da capa",IF(B10="FAIXA_50","Faixa Reflecta 50%",IF(B10="FAIXA_MONTAGEM","Faixa de montagem",IF(B10="VIXCLUB","Painel VixClub (ocupa o que sobrar)",COUNTIF(Produtos!$A:$A,B10)&" produtos")))))
A11: 4 | B11: FAIXA_50 | C11: =IF(B11="","",IF(B11="CAPA","Cabeçalho da capa",IF(B11="FAIXA_50","Faixa Reflecta 50%",IF(B11="FAIXA_MONTAGEM","Faixa de montagem",IF(B11="VIXCLUB","Painel VixClub (ocupa o que sobrar)",COUNTIF(Produtos!$A:$A,B11)&" produtos")))))
A12: 4 | B12: KODAK NETWORK UHD | C12: =IF(B12="","",IF(B12="CAPA","Cabeçalho da capa",IF(B12="FAIXA_50","Faixa Reflecta 50%",IF(B12="FAIXA_MONTAGEM","Faixa de montagem",IF(B12="VIXCLUB","Painel VixClub (ocupa o que sobrar)",COUNTIF(Produtos!$A:$A,B12)&" produtos")))))
A13: 4 | B13: KODAK SOFTWEAR | C13: =IF(B13="","",IF(B13="CAPA","Cabeçalho da capa",IF(B13="FAIXA_50","Faixa Reflecta 50%",IF(B13="FAIXA_MONTAGEM","Faixa de montagem",IF(B13="VIXCLUB","Painel VixClub (ocupa o que sobrar)",COUNTIF(Produtos!$A:$A,B13)&" produtos")))))
A14: 5 | B14: KODAK UNIQUE UHD | C14: =IF(B14="","",IF(B14="CAPA","Cabeçalho da capa",IF(B14="FAIXA_50","Faixa Reflecta 50%",IF(B14="FAIXA_MONTAGEM","Faixa de montagem",IF(B14="VIXCLUB","Painel VixClub (ocupa o que sobrar)",COUNTIF(Produtos!$A:$A,B14)&" produtos")))))
... A22: 8 | B22: SOLAR ACABADA | C22: =IF(B22="","",IF(B22="CAPA","Cabeçalho da capa",IF(B22="FAIXA_50","Faixa Reflecta 50%",IF(B22="FAIXA_MONTAGEM","Faixa de montagem",IF(B22="VIXCLUB","Painel VixClub (ocupa o que sobrar)",COUNTIF(Produtos!$A:$A,B22)&" produtos")))))
C23: =IF(B23="","",IF(B23="CAPA","Cabeçalho da capa",IF(B23="FAIXA_50","Faixa Reflecta 50%",IF(B23="FAIXA_MONTAGEM","Faixa de montagem",IF(B23="VIXCLUB","Painel VixClub (ocupa o que sobrar)",COUNTIF(Produtos!$A:$A,B23)&" produtos")))))
C24: =IF(B24="","",IF(B24="CAPA","Cabeçalho da capa",IF(B24="FAIXA_50","Faixa Reflecta 50%",IF(B24="FAIXA_MONTAGEM","Faixa de montagem",IF(B24="VIXCLUB","Painel VixClub (ocupa o que sobrar)",COUNTIF(Produtos!$A:$A,B24)&" produtos")))))
C25: =IF(B25="","",IF(B25="CAPA","Cabeçalho da capa",IF(B25="FAIXA_50","Faixa Reflecta 50%",IF(B25="FAIXA_MONTAGEM","Faixa de montagem",IF(B25="VIXCLUB","Painel VixClub (ocupa o que sobrar)",COUNTIF(Produtos!$A:$A,B25)&" produtos")))))
C26: =IF(B26="","",IF(B26="CAPA","Cabeçalho da capa",IF(B26="FAIXA_50","Faixa Reflecta 50%",IF(B26="FAIXA_MONTAGEM","Faixa de montagem",IF(B26="VIXCLUB","Painel VixClub (ocupa o que sobrar)",COUNTIF(Produtos!$A:$A,B26)&" produtos")))))
C27: =IF(B27="","",IF(B27="CAPA","Cabeçalho da capa",IF(B27="FAIXA_50","Faixa Reflecta 50%",IF(B27="FAIXA_MONTAGEM","Faixa de montagem",IF(B27="VIXCLUB","Painel VixClub (ocupa o que sobrar)",COUNTIF(Produtos!$A:$A,B27)&" produtos")))))
C28: =IF(B28="","",IF(B28="CAPA","Cabeçalho da capa",IF(B28="FAIXA_50","Faixa Reflecta 50%",IF(B28="FAIXA_MONTAGEM","Faixa de montagem",IF(B28="VIXCLUB","Painel VixClub (ocupa o que sobrar)",COUNTIF(Produtos!$A:$A,B28)&" produtos")))))
C29: =IF(B29="","",IF(B29="CAPA","Cabeçalho da capa",IF(B29="FAIXA_50","Faixa Reflecta 50%",IF(B29="FAIXA_MONTAGEM","Faixa de montagem",IF(B29="VIXCLUB","Painel VixClub (ocupa o que sobrar)",COUNTIF(Produtos!$A:$A,B29)&" produtos")))))
C30: =IF(B30="","",IF(B30="CAPA","Cabeçalho da capa",IF(B30="FAIXA_50","Faixa Reflecta 50%",IF(B30="FAIXA_MONTAGEM","Faixa de montagem",IF(B30="VIXCLUB","Painel VixClub (ocupa o que sobrar)",COUNTIF(Produtos!$A:$A,B30)&" produtos")))))
C31: =IF(B31="","",IF(B31="CAPA","Cabeçalho da capa",IF(B31="FAIXA_50","Faixa Reflecta 50%",IF(B31="FAIXA_MONTAGEM","Faixa de montagem",IF(B31="VIXCLUB","Painel VixClub (ocupa o que sobrar)",COUNTIF(Produtos!$A:$A,B31)&" produtos")))))
C32: =IF(B32="","",IF(B32="CAPA","Cabeçalho da capa",IF(B32="FAIXA_50","Faixa Reflecta 50%",IF(B32="FAIXA_MONTAGEM","Faixa de montagem",IF(B32="VIXCLUB","Painel VixClub (ocupa o que sobrar)",COUNTIF(Produtos!$A:$A,B32)&" produtos")))))
C33: =IF(B33="","",IF(B33="CAPA","Cabeçalho da capa",IF(B33="FAIXA_50","Faixa Reflecta 50%",IF(B33="FAIXA_MONTAGEM","Faixa de montagem",IF(B33="VIXCLUB","Painel VixClub (ocupa o que sobrar)",COUNTIF(Produtos!$A:$A,B33)&" produtos")))))
C34: =IF(B34="","",IF(B34="CAPA","Cabeçalho da capa",IF(B34="FAIXA_50","Faixa Reflecta 50%",IF(B34="FAIXA_MONTAGEM","Faixa de montagem",IF(B34="VIXCLUB","Painel VixClub (ocupa o que sobrar)",COUNTIF(Produtos!$A:$A,B34)&" produtos")))))
... C60: =IF(B60="","",IF(B60="CAPA","Cabeçalho da capa",IF(B60="FAIXA_50","Faixa Reflecta 50%",IF(B60="FAIXA_MONTAGEM","Faixa de montagem",IF(B60="VIXCLUB","Painel VixClub (ocupa o que sobrar)",COUNTIF(Produtos!$A:$A,B60)&" produtos")))))

Sheet Listas
A1: CAPA
A2: FAIXA_50
A3: FAIXA_MONTAGEM
A4: VIXCLUB
A5: =IF('Famílias'!A3="","",'Famílias'!A3)
A6: =IF('Famílias'!A4="","",'Famílias'!A4)
A7: =IF('Famílias'!A5="","",'Famílias'!A5)
A8: =IF('Famílias'!A6="","",'Famílias'!A6)
A9: =IF('Famílias'!A7="","",'Famílias'!A7)
A10: =IF('Famílias'!A8="","",'Famílias'!A8)
A11: =IF('Famílias'!A9="","",'Famílias'!A9)
A12: =IF('Famílias'!A10="","",'Famílias'!A10)
A13: =IF('Famílias'!A11="","",'Famílias'!A11)
A14: =IF('Famílias'!A12="","",'Famílias'!A12)
A15: =IF('Famílias'!A13="","",'Famílias'!A13)
A16: =IF('Famílias'!A14="","",'Famílias'!A14)
... A82: =IF('Famílias'!A80="","",'Famílias'!A80)
